try{
    const t=5/0;
}catch{
    console.log("encounter an error");
}finally{
    console.log("try and catch been executed");
}